Workbook

Sheet Key Ratio
A1: KEY RATIO - PT Rukun Raharja Tbk (RAJA)
A4: Keterangan | B4: 12M 2016 | C4: 12M 2017 | D4: 12M 2018 | E4: 12M 2019 | F4: 12M 2020 | G4: 12M 2021 | H4: 12M 2022 | I4: 12M 2023 | J4: 12M 2024 | K4: 12M 2025 | M4: Catatan
A5: VALUASI & PROFITABILITAS
A6: Share Outstanding (Miliar Lembar) | B6: =INDEX('Income Statement'!$B$42:$K$42,MATCH(B$4,'Income Statement'!$B$4:$K$4,0)) -> 4.08 | C6: =INDEX('Income Statement'!$B$42:$K$42,MATCH(C$4,'Income Statement'!$B$4:$K$4,0)) -> 4.08 | D6: =INDEX('Income Statement'!$B$42:$K$42,MATCH(D$4,'Income Statement'!$B$4:$K$4,0)) -> 4.23 | E6: =INDEX('Income Statement'!$B$42:$K$42,MATCH(E$4,'Income Statement'!$B$4:$K$4,0)) -> 4.23 | F6: =INDEX('Income Statement'!$B$42:$K$42,MATCH(F$4,'Income Statement'!$B$4:$K$4,0)) -> 4.23 | G6: =INDEX('Income Statement'!$B$42:$K$42,MATCH(G$4,'Income Statement'!$B$4:$K$4,0)) -> 4.23 | H6: =INDEX('Income Statement'!$B$42:$K$42,MATCH(H$4,'Income Statement'!$B$4:$K$4,0)) -> 4.23 | I6: =INDEX('Income Statement'!$B$42:$K$42,MATCH(I$4,'Income Statement'!$B$4:$K$4,0)) -> 4.23 | ... K6: =INDEX('Income Statement'!$B$42:$K$42,MATCH(K$4,'Income Statement'!$B$4:$K$4,0)) -> 4.23
A7: EPS (Annual) (Rp) | B7: =INDEX('Income Statement'!$B$30:$K$30,MATCH(B$4,'Income Statement'!$B$4:$K$4,0))/B6 -> 21.323529 | C7: =INDEX('Income Statement'!$B$30:$K$30,MATCH(C$4,'Income Statement'!$B$4:$K$4,0))/C6 -> 38.235294 | D7: =INDEX('Income Statement'!$B$30:$K$30,MATCH(D$4,'Income Statement'!$B$4:$K$4,0))/D6 -> 38.534279 | E7: =INDEX('Income Statement'!$B$30:$K$30,MATCH(E$4,'Income Statement'!$B$4:$K$4,0))/E6 -> 19.148936 | F7: =INDEX('Income Statement'!$B$30:$K$30,MATCH(F$4,'Income Statement'!$B$4:$K$4,0))/F6 -> 4.7281324 | G7: =INDEX('Income Statement'!$B$30:$K$30,MATCH(G$4,'Income Statement'!$B$4:$K$4,0))/G6 -> 7.5650118 | H7: =INDEX('Income Statement'!$B$30:$K$30,MATCH(H$4,'Income Statement'!$B$4:$K$4,0))/H6 -> 30.969267 | I7: =INDEX('Income Statement'!$B$30:$K$30,MATCH(I$4,'Income Statement'!$B$4:$K$4,0))/I6 -> 92.434988 | ... K7: =INDEX('Income Statement'!$B$30:$K$30,MATCH(K$4,'Income Statement'!$B$4:$K$4,0))/K6 -> 106.14657
A8: PE Ratio (Annual) | B8: =INDEX('Market Data'!$B$31:$K$31,MATCH(B$4,'Market Data'!$B$24:$K$24,0)) -> 9.3793103 | C8: =INDEX('Market Data'!$B$31:$K$31,MATCH(C$4,'Market Data'!$B$24:$K$24,0)) -> 7.8461538 | D8: =INDEX('Market Data'!$B$31:$K$31,MATCH(D$4,'Market Data'!$B$24:$K$24,0)) -> 8.4340491 | E8: =INDEX('Market Data'!$B$31:$K$31,MATCH(E$4,'Market Data'!$B$24:$K$24,0)) -> 9.9222222 | F8: =INDEX('Market Data'!$B$31:$K$31,MATCH(F$4,'Market Data'!$B$24:$K$24,0)) -> 52.875 | G8: =INDEX('Market Data'!$B$31:$K$31,MATCH(G$4,'Market Data'!$B$24:$K$24,0)) -> 23.79375 | H8: =INDEX('Market Data'!$B$31:$K$31,MATCH(H$4,'Market Data'!$B$24:$K$24,0)) -> 33.90458 | I8: =INDEX('Market Data'!$B$31:$K$31,MATCH(I$4,'Market Data'!$B$24:$K$24,0)) -> 15.253964 | ... K8: =INDEX('Market Data'!$B$31:$K$31,MATCH(K$4,'Market Data'!$B$24:$K$24,0)) -> 57.467706
A9: Price to Sales (Annual) | B9: =INDEX('Market Data'!$B$32:$K$32,MATCH(B$4,'Market Data'!$B$24:$K$24,0)) -> 0.32810615 | C9: =INDEX('Market Data'!$B$32:$K$32,MATCH(C$4,'Market Data'!$B$24:$K$24,0)) -> 0.61414952 | D9: =INDEX('Market Data'!$B$32:$K$32,MATCH(D$4,'Market Data'!$B$24:$K$24,0)) -> 0.81684492 | E9: =INDEX('Market Data'!$B$32:$K$32,MATCH(E$4,'Market Data'!$B$24:$K$24,0)) -> 0.46510417 | F9: =INDEX('Market Data'!$B$32:$K$32,MATCH(F$4,'Market Data'!$B$24:$K$24,0)) -> 0.734375 | G9: =INDEX('Market Data'!$B$32:$K$32,MATCH(G$4,'Market Data'!$B$24:$K$24,0)) -> 0.54192171 | H9: =INDEX('Market Data'!$B$32:$K$32,MATCH(H$4,'Market Data'!$B$24:$K$24,0)) -> 2.3562334 | I9: =INDEX('Market Data'!$B$32:$K$32,MATCH(I$4,'Market Data'!$B$24:$K$24,0)) -> 1.9190154 | ... K9: =INDEX('Market Data'!$B$32:$K$32,MATCH(K$4,'Market Data'!$B$24:$K$24,0)) -> 5.8723259
A10: EBITDA (Annual) | B10: n/a | C10: n/a | D10: 184.57 | E10: 136.69 | F10: 187.66 | G10: 175.74 | H10: 334.92 | I10: 1000.02 | J10: 1105.93 | K10: 1126.33
A11: Return on Assets - ROA (Annual) | B11: =INDEX('Income Statement'!$B$30:$K$30,MATCH(B$4,'Income Statement'!$B$4:$K$4,0))/INDEX('Balance Sheet'!$B$26:$K$26,MATCH(B$4,'Balance Sheet'!$B$4:$K$4,0)) -> 0.044592517 | C11: =INDEX('Income Statement'!$B$30:$K$30,MATCH(C$4,'Income Statement'!$B$4:$K$4,0))/INDEX('Balance Sheet'!$B$26:$K$26,MATCH(C$4,'Balance Sheet'!$B$4:$K$4,0)) -> 0.076508092 | D11: =INDEX('Income Statement'!$B$30:$K$30,MATCH(D$4,'Income Statement'!$B$4:$K$4,0))/INDEX('Balance Sheet'!$B$26:$K$26,MATCH(D$4,'Balance Sheet'!$B$4:$K$4,0)) -> 0.058908565 | E11: =INDEX('Income Statement'!$B$30:$K$30,MATCH(E$4,'Income Statement'!$B$4:$K$4,0))/INDEX('Balance Sheet'!$B$26:$K$26,MATCH(E$4,'Balance Sheet'!$B$4:$K$4,0)) -> 0.032296651 | F11: =INDEX('Income Statement'!$B$30:$K$30,MATCH(F$4,'Income Statement'!$B$4:$K$4,0))/INDEX('Balance Sheet'!$B$26:$K$26,MATCH(F$4,'Balance Sheet'!$B$4:$K$4,0)) -> 0.0085070183 | G11: =INDEX('Income Statement'!$B$30:$K$30,MATCH(G$4,'Income Statement'!$B$4:$K$4,0))/INDEX('Balance Sheet'!$B$26:$K$26,MATCH(G$4,'Balance Sheet'!$B$4:$K$4,0)) -> 0.0091272105 | H11: =INDEX('Income Statement'!$B$30:$K$30,MATCH(H$4,'Income Statement'!$B$4:$K$4,0))/INDEX('Balance Sheet'!$B$26:$K$26,MATCH(H$4,'Balance Sheet'!$B$4:$K$4,0)) -> 0.032250123 | I11: =INDEX('Income Statement'!$B$30:$K$30,MATCH(I$4,'Income Statement'!$B$4:$K$4,0))/INDEX('Balance Sheet'!$B$26:$K$26,MATCH(I$4,'Balance Sheet'!$B$4:$K$4,0)) -> 0.077059519 | ... K11: =INDEX('Income Statement'!$B$30:$K$30,MATCH(K$4,'Income Statement'!$B$4:$K$4,0))/INDEX('Balance Sheet'!$B$26:$K$26,MATCH(K$4,'Balance Sheet'!$B$4:$K$4,0)) -> 0.056223391
A12: Return on Equity - ROE (Annual) | B12: =INDEX('Income Statement'!$B$30:$K$30,MATCH(B$4,'Income Statement'!$B$4:$K$4,0))/(INDEX('Balance Sheet'!$B$77:$K$77,MATCH(B$4,'Balance Sheet'!$B$4:$K$4,0))-INDEX('Balance Sheet'!$B$75:$K$75,MATCH(B$4,'Balance Sheet'!$B$4:$K$4,0))) -> 0.093952484 | C12: =INDEX('Income Statement'!$B$30:$K$30,MATCH(C$4,'Income Statement'!$B$4:$K$4,0))/(INDEX('Balance Sheet'!$B$77:$K$77,MATCH(C$4,'Balance Sheet'!$B$4:$K$4,0))-INDEX('Balance Sheet'!$B$75:$K$75,MATCH(C$4,'Balance Sheet'!$B$4:$K$4,0))) -> 0.14511628 | D12: =INDEX('Income Statement'!$B$30:$K$30,MATCH(D$4,'Income Statement'!$B$4:$K$4,0))/(INDEX('Balance Sheet'!$B$77:$K$77,MATCH(D$4,'Balance Sheet'!$B$4:$K$4,0))-INDEX('Balance Sheet'!$B$75:$K$75,MATCH(D$4,'Balance Sheet'!$B$4:$K$4,0))) -> 0.12264861 | E12: =INDEX('Income Statement'!$B$30:$K$30,MATCH(E$4,'Income Statement'!$B$4:$K$4,0))/(INDEX('Balance Sheet'!$B$77:$K$77,MATCH(E$4,'Balance Sheet'!$B$4:$K$4,0))-INDEX('Balance Sheet'!$B$75:$K$75,MATCH(E$4,'Balance Sheet'!$B$4:$K$4,0))) -> 0.057569296 | F12: =INDEX('Income Statement'!$B$30:$K$30,MATCH(F$4,'Income Statement'!$B$4:$K$4,0))/(INDEX('Balance Sheet'!$B$77:$K$77,MATCH(F$4,'Balance Sheet'!$B$4:$K$4,0))-INDEX('Balance Sheet'!$B$75:$K$75,MATCH(F$4,'Balance Sheet'!$B$4:$K$4,0))) -> 0.014054814 | G12: =INDEX('Income Statement'!$B$30:$K$30,MATCH(G$4,'Income Statement'!$B$4:$K$4,0))/(INDEX('Balance Sheet'!$B$77:$K$77,MATCH(G$4,'Balance Sheet'!$B$4:$K$4,0))-INDEX('Balance Sheet'!$B$75:$K$75,MATCH(G$4,'Balance Sheet'!$B$4:$K$4,0))) -> 0.0220234 | H12: =INDEX('Income Statement'!$B$30:$K$30,MATCH(H$4,'Income Statement'!$B$4:$K$4,0))/(INDEX('Balance Sheet'!$B$77:$K$77,MATCH(H$4,'Balance Sheet'!$B$4:$K$4,0))-INDEX('Balance Sheet'!$B$75:$K$75,MATCH(H$4,'Balance Sheet'!$B$4:$K$4,0))) -> 0.077331759 | I12: =INDEX('Income Statement'!$B$30:$K$30,MATCH(I$4,'Income Statement'!$B$4:$K$4,0))/(INDEX('Balance Sheet'!$B$77:$K$77,MATCH(I$4,'Balance Sheet'!$B$4:$K$4,0))-INDEX('Balance Sheet'!$B$75:$K$75,MATCH(I$4,'Balance Sheet'!$B$4:$K$4,0))) -> 0.1954023 | ... K12: =INDEX('Income Statement'!$B$30:$K$30,MATCH(K$4,'Income Statement'!$B$4:$K$4,0))/(INDEX('Balance Sheet'!$B$77:$K$77,MATCH(K$4,'Balance Sheet'!$B$4:$K$4,0))-INDEX('Balance Sheet'!$B$75:$K$75,MATCH(K$4,'Balance Sheet'!$B$4:$K$4,0))) -> 0.1260174
A13: Return on Capital Employed - ROCE (Annual) | B13: =INDEX('Income Statement'!$B$9:$K$9,MATCH(B$4,'Income Statement'!$B$4:$K$4,0))/(INDEX('Balance Sheet'!$B$26:$K$26,MATCH(B$4,'Balance Sheet'!$B$4:$K$4,0))-INDEX('Balance Sheet'!$B$50:$K$50,MATCH(B$4,'Balance Sheet'!$B$4:$K$4,0))) -> 0.093446602 | C13: =INDEX('Income Statement'!$B$9:$K$9,MATCH(C$4,'Income Statement'!$B$4:$K$4,0))/(INDEX('Balance Sheet'!$B$26:$K$26,MATCH(C$4,'Balance Sheet'!$B$4:$K$4,0))-INDEX('Balance Sheet'!$B$50:$K$50,MATCH(C$4,'Balance Sheet'!$B$4:$K$4,0))) -> 0.014899713 | D13: =INDEX('Income Statement'!$B$9:$K$9,MATCH(D$4,'Income Statement'!$B$4:$K$4,0))/(INDEX('Balance Sheet'!$B$26:$K$26,MATCH(D$4,'Balance Sheet'!$B$4:$K$4,0))-INDEX('Balance Sheet'!$B$50:$K$50,MATCH(D$4,'Balance Sheet'!$B$4:$K$4,0))) -> 0.035073735 | E13: =INDEX('Income Statement'!$B$9:$K$9,MATCH(E$4,'Income Statement'!$B$4:$K$4,0))/(INDEX('Balance Sheet'!$B$26:$K$26,MATCH(E$4,'Balance Sheet'!$B$4:$K$4,0))-INDEX('Balance Sheet'!$B$50:$K$50,MATCH(E$4,'Balance Sheet'!$B$4:$K$4,0))) -> 0.018340211 | F13: =INDEX('Income Statement'!$B$9:$K$9,MATCH(F$4,'Income Statement'!$B$4:$K$4,0))/(INDEX('Balance Sheet'!$B$26:$K$26,MATCH(F$4,'Balance Sheet'!$B$4:$K$4,0))-INDEX('Balance Sheet'!$B$50:$K$50,MATCH(F$4,'Balance Sheet'!$B$4:$K$4,0))) -> 0.04062653 | G13: =INDEX('Income Statement'!$B$9:$K$9,MATCH(G$4,'Income Statement'!$B$4:$K$4,0))/(INDEX('Balance Sheet'!$B$26:$K$26,MATCH(G$4,'Balance Sheet'!$B$4:$K$4,0))-INDEX('Balance Sheet'!$B$50:$K$50,MATCH(G$4,'Balance Sheet'!$B$4:$K$4,0))) -> 0.020465116 | H13: =INDEX('Income Statement'!$B$9:$K$9,MATCH(H$4,'Income Statement'!$B$4:$K$4,0))/(INDEX('Balance Sheet'!$B$26:$K$26,MATCH(H$4,'Balance Sheet'!$B$4:$K$4,0))-INDEX('Balance Sheet'!$B$50:$K$50,MATCH(H$4,'Balance Sheet'!$B$4:$K$4,0))) -> 0.050535567 | I13: =INDEX('Income Statement'!$B$9:$K$9,MATCH(I$4,'Income Statement'!$B$4:$K$4,0))/(INDEX('Balance Sheet'!$B$26:$K$26,MATCH(I$4,'Balance Sheet'!$B$4:$K$4,0))-INDEX('Balance Sheet'!$B$50:$K$50,MATCH(I$4,'Balance Sheet'!$B$4:$K$4,0))) -> 0.17435775 | ... K13: =INDEX('Income Statement'!$B$9:$K$9,MATCH(K$4,'Income Statement'!$B$4:$K$4,0))/(INDEX('Balance Sheet'!$B$26:$K$26,MATCH(K$4,'Balance Sheet'!$B$4:$K$4,0))-INDEX('Balance Sheet'!$B$50:$K$50,MATCH(K$4,'Balance Sheet'!$B$4:$K$4,0))) -> 0.12077597
A14: Interest Coverage (Annual) | B14: =INDEX('Income Statement'!$B$9:$K$9,MATCH(B$4,'Income Statement'!$B$4:$K$4,0))/ABS(INDEX('Income Statement'!$B$14:$K$14,MATCH(B$4,'Income Statement'!$B$4:$K$4,0))) -> 2.9615385 | C14: =INDEX('Income Statement'!$B$9:$K$9,MATCH(C$4,'Income Statement'!$B$4:$K$4,0))/ABS(INDEX('Income Statement'!$B$14:$K$14,MATCH(C$4,'Income Statement'!$B$4:$K$4,0))) -> 0.35135135 | D14: =INDEX('Income Statement'!$B$9:$K$9,MATCH(D$4,'Income Statement'!$B$4:$K$4,0))/ABS(INDEX('Income Statement'!$B$14:$K$14,MATCH(D$4,'Income Statement'!$B$4:$K$4,0))) -> 0.93617021 | E14: =INDEX('Income Statement'!$B$9:$K$9,MATCH(E$4,'Income Statement'!$B$4:$K$4,0))/ABS(INDEX('Income Statement'!$B$14:$K$14,MATCH(E$4,'Income Statement'!$B$4:$K$4,0))) -> 0.85106383 | F14: =INDEX('Income Statement'!$B$9:$K$9,MATCH(F$4,'Income Statement'!$B$4:$K$4,0))/ABS(INDEX('Income Statement'!$B$14:$K$14,MATCH(F$4,'Income Statement'!$B$4:$K$4,0))) -> 1.8863636 | G14: =INDEX('Income Statement'!$B$9:$K$9,MATCH(G$4,'Income Statement'!$B$4:$K$4,0))/ABS(INDEX('Income Statement'!$B$14:$K$14,MATCH(G$4,'Income Statement'!$B$4:$K$4,0))) -> 1.8857143 | H14: =INDEX('Income Statement'!$B$9:$K$9,MATCH(H$4,'Income Statement'!$B$4:$K$4,0))/ABS(INDEX('Income Statement'!$B$14:$K$14,MATCH(H$4,'Income Statement'!$B$4:$K$4,0))) -> 4.6 | I14: =INDEX('Income Statement'!$B$9:$K$9,MATCH(I$4,'Income Statement'!$B$4:$K$4,0))/ABS(INDEX('Income Statement'!$B$14:$K$14,MATCH(I$4,'Income Statement'!$B$4:$K$4,0))) -> 5.1985816 | ... K14: =INDEX('Income Statement'!$B$9:$K$9,MATCH(K$4,'Income Statement'!$B$4:$K$4,0))/ABS(INDEX('Income Statement'!$B$14:$K$14,MATCH(K$4,'Income Statement'!$B$4:$K$4,0))) -> 4.6506024
A16: VALUASI BUKU (BOOK VALUE)
A17: Price to Book Value (Annual) | B17: =INDEX('Market Data'!$B$33:$K$33,MATCH(B$4,'Market Data'!$B$24:$K$24,0)) -> 0.8812095 | C17: =INDEX('Market Data'!$B$33:$K$33,MATCH(C$4,'Market Data'!$B$24:$K$24,0)) -> 1.1386047 | D17: =INDEX('Market Data'!$B$33:$K$33,MATCH(D$4,'Market Data'!$B$24:$K$24,0)) -> 1.0344244 | E17: =INDEX('Market Data'!$B$33:$K$33,MATCH(E$4,'Market Data'!$B$24:$K$24,0)) -> 0.57121535 | F17: =INDEX('Market Data'!$B$33:$K$33,MATCH(F$4,'Market Data'!$B$24:$K$24,0)) -> 0.74314828 | G17: =INDEX('Market Data'!$B$33:$K$33,MATCH(G$4,'Market Data'!$B$24:$K$24,0)) -> 0.52401927 | H17: =INDEX('Market Data'!$B$33:$K$33,MATCH(H$4,'Market Data'!$B$24:$K$24,0)) -> 2.6219008 | I17: =INDEX('Market Data'!$B$33:$K$33,MATCH(I$4,'Market Data'!$B$24:$K$24,0)) -> 2.9806597 | ... K17: =INDEX('Market Data'!$B$33:$K$33,MATCH(K$4,'Market Data'!$B$24:$K$24,0)) -> 7.241931
A18: Book Value Per Share (Rp) | B18: =(INDEX('Balance Sheet'!$B$77:$K$77,MATCH(B$4,'Balance Sheet'!$B$4:$K$4,0))-INDEX('Balance Sheet'!$B$75:$K$75,MATCH(B$4,'Balance Sheet'!$B$4:$K$4,0)))/B6 -> 226.96078 | C18: =(INDEX('Balance Sheet'!$B$77:$K$77,MATCH(C$4,'Balance Sheet'!$B$4:$K$4,0))-INDEX('Balance Sheet'!$B$75:$K$75,MATCH(C$4,'Balance Sheet'!$B$4:$K$4,0)))/C6 -> 263.48039 | D18: =(INDEX('Balance Sheet'!$B$77:$K$77,MATCH(D$4,'Balance Sheet'!$B$4:$K$4,0))-INDEX('Balance Sheet'!$B$75:$K$75,MATCH(D$4,'Balance Sheet'!$B$4:$K$4,0)))/D6 -> 314.1844 | E18: =(INDEX('Balance Sheet'!$B$77:$K$77,MATCH(E$4,'Balance Sheet'!$B$4:$K$4,0))-INDEX('Balance Sheet'!$B$75:$K$75,MATCH(E$4,'Balance Sheet'!$B$4:$K$4,0)))/E6 -> 332.62411 | F18: =(INDEX('Balance Sheet'!$B$77:$K$77,MATCH(F$4,'Balance Sheet'!$B$4:$K$4,0))-INDEX('Balance Sheet'!$B$75:$K$75,MATCH(F$4,'Balance Sheet'!$B$4:$K$4,0)))/F6 -> 336.40662 | G18: =(INDEX('Balance Sheet'!$B$77:$K$77,MATCH(G$4,'Balance Sheet'!$B$4:$K$4,0))-INDEX('Balance Sheet'!$B$75:$K$75,MATCH(G$4,'Balance Sheet'!$B$4:$K$4,0)))/G6 -> 343.49882 | H18: =(INDEX('Balance Sheet'!$B$77:$K$77,MATCH(H$4,'Balance Sheet'!$B$4:$K$4,0))-INDEX('Balance Sheet'!$B$75:$K$75,MATCH(H$4,'Balance Sheet'!$B$4:$K$4,0)))/H6 -> 400.47281 | I18: =(INDEX('Balance Sheet'!$B$77:$K$77,MATCH(I$4,'Balance Sheet'!$B$4:$K$4,0))-INDEX('Balance Sheet'!$B$75:$K$75,MATCH(I$4,'Balance Sheet'!$B$4:$K$4,0)))/I6 -> 473.04965 | ... K18: =(INDEX('Balance Sheet'!$B$77:$K$77,MATCH(K$4,'Balance Sheet'!$B$4:$K$4,0))-INDEX('Balance Sheet'!$B$75:$K$75,MATCH(K$4,'Balance Sheet'!$B$4:$K$4,0)))/K6 -> 842.31678
A19: Price to Tangible Book Value (Annual) | B19: =INDEX('Market Data'!$B$34:$K$34,MATCH(B$4,'Market Data'!$B$24:$K$24,0)) -> 1.2769761 | C19: =INDEX('Market Data'!$B$34:$K$34,MATCH(C$4,'Market Data'!$B$24:$K$24,0)) -> 1.5598191 | D19: =INDEX('Market Data'!$B$34:$K$34,MATCH(D$4,'Market Data'!$B$24:$K$24,0)) -> 1.3481561 | E19: =INDEX('Market Data'!$B$34:$K$34,MATCH(E$4,'Market Data'!$B$24:$K$24,0)) -> 0.72466532 | F19: =INDEX('Market Data'!$B$34:$K$34,MATCH(F$4,'Market Data'!$B$24:$K$24,0)) -> 0.94240048 | G19: =INDEX('Market Data'!$B$34:$K$34,MATCH(G$4,'Market Data'!$B$24:$K$24,0)) -> 0.70028011 | H19: =INDEX('Market Data'!$B$34:$K$34,MATCH(H$4,'Market Data'!$B$24:$K$24,0)) -> 3.443865 | I19: =INDEX('Market Data'!$B$34:$K$34,MATCH(I$4,'Market Data'!$B$24:$K$24,0)) -> 3.719041 | ... K19: =INDEX('Market Data'!$B$34:$K$34,MATCH(K$4,'Market Data'!$B$24:$K$24,0)) -> 8.2436888
A20: Tangible Book Value Per Share (Rp) | B20: 156.62 | C20: 192.33 | D20: 241.07 | E20: 262.19 | F20: 265.28 | G20: 257.04 | H20: 304.89 | I20: 379.13 | J20: 448.22 | K20: 739.96
A22: STRUKTUR UTANG (DEBT)
A23: Short-term Debt (Annual) | B23: =INDEX('Balance Sheet'!$B$31:$K$31,MATCH(B$4,'Balance Sheet'!$B$4:$K$4,0))+INDEX('Balance Sheet'!$B$44:$K$44,MATCH(B$4,'Balance Sheet'!$B$4:$K$4,0))+INDEX('Balance Sheet'!$B$46:$K$46,MATCH(B$4,'Balance Sheet'!$B$4:$K$4,0)) -> 208 | C23: =INDEX('Balance Sheet'!$B$31:$K$31,MATCH(C$4,'Balance Sheet'!$B$4:$K$4,0))+INDEX('Balance Sheet'!$B$44:$K$44,MATCH(C$4,'Balance Sheet'!$B$4:$K$4,0))+INDEX('Balance Sheet'!$B$46:$K$46,MATCH(C$4,'Balance Sheet'!$B$4:$K$4,0)) -> 104 | D23: =INDEX('Balance Sheet'!$B$31:$K$31,MATCH(D$4,'Balance Sheet'!$B$4:$K$4,0))+INDEX('Balance Sheet'!$B$44:$K$44,MATCH(D$4,'Balance Sheet'!$B$4:$K$4,0))+INDEX('Balance Sheet'!$B$46:$K$46,MATCH(D$4,'Balance Sheet'!$B$4:$K$4,0)) -> 97 | E23: =INDEX('Balance Sheet'!$B$31:$K$31,MATCH(E$4,'Balance Sheet'!$B$4:$K$4,0))+INDEX('Balance Sheet'!$B$44:$K$44,MATCH(E$4,'Balance Sheet'!$B$4:$K$4,0))+INDEX('Balance Sheet'!$B$46:$K$46,MATCH(E$4,'Balance Sheet'!$B$4:$K$4,0)) -> 168 | F23: =INDEX('Balance Sheet'!$B$31:$K$31,MATCH(F$4,'Balance Sheet'!$B$4:$K$4,0))+INDEX('Balance Sheet'!$B$44:$K$44,MATCH(F$4,'Balance Sheet'!$B$4:$K$4,0))+INDEX('Balance Sheet'!$B$46:$K$46,MATCH(F$4,'Balance Sheet'!$B$4:$K$4,0)) -> 156 | G23: =INDEX('Balance Sheet'!$B$31:$K$31,MATCH(G$4,'Balance Sheet'!$B$4:$K$4,0))+INDEX('Balance Sheet'!$B$44:$K$44,MATCH(G$4,'Balance Sheet'!$B$4:$K$4,0))+INDEX('Balance Sheet'!$B$46:$K$46,MATCH(G$4,'Balance Sheet'!$B$4:$K$4,0)) -> 126 | H23: =INDEX('Balance Sheet'!$B$31:$K$31,MATCH(H$4,'Balance Sheet'!$B$4:$K$4,0))+INDEX('Balance Sheet'!$B$44:$K$44,MATCH(H$4,'Balance Sheet'!$B$4:$K$4,0))+INDEX('Balance Sheet'!$B$46:$K$46,MATCH(H$4,'Balance Sheet'!$B$4:$K$4,0)) -> 186 | I23: =INDEX('Balance Sheet'!$B$31:$K$31,MATCH(I$4,'Balance Sheet'!$B$4:$K$4,0))+INDEX('Balance Sheet'!$B$44:$K$44,MATCH(I$4,'Balance Sheet'!$B$4:$K$4,0))+INDEX('Balance Sheet'!$B$46:$K$46,MATCH(I$4,'Balance Sheet'!$B$4:$K$4,0)) -> 437 | ... K23: =INDEX('Balance Sheet'!$B$31:$K$31,MATCH(K$4,'Balance Sheet'!$B$4:$K$4,0))+INDEX('Balance Sheet'!$B$44:$K$44,MATCH(K$4,'Balance Sheet'!$B$4:$K$4,0))+INDEX('Balance Sheet'!$B$46:$K$46,MATCH(K$4,'Balance Sheet'!$B$4:$K$4,0)) -> 722
A24: Long-term Debt (Annual) | B24: =INDEX('Balance Sheet'!$B$55:$K$55,MATCH(B$4,'Balance Sheet'!$B$4:$K$4,0))+INDEX('Balance Sheet'!$B$57:$K$57,MATCH(B$4,'Balance Sheet'!$B$4:$K$4,0)) -> 396 | C24: =INDEX('Balance Sheet'!$B$55:$K$55,MATCH(C$4,'Balance Sheet'!$B$4:$K$4,0))+INDEX('Balance Sheet'!$B$57:$K$57,MATCH(C$4,'Balance Sheet'!$B$4:$K$4,0)) -> 96 | D24: =INDEX('Balance Sheet'!$B$55:$K$55,MATCH(D$4,'Balance Sheet'!$B$4:$K$4,0))+INDEX('Balance Sheet'!$B$57:$K$57,MATCH(D$4,'Balance Sheet'!$B$4:$K$4,0)) -> 582 | E24: =INDEX('Balance Sheet'!$B$55:$K$55,MATCH(E$4,'Balance Sheet'!$B$4:$K$4,0))+INDEX('Balance Sheet'!$B$57:$K$57,MATCH(E$4,'Balance Sheet'!$B$4:$K$4,0)) -> 454 | F24: =INDEX('Balance Sheet'!$B$55:$K$55,MATCH(F$4,'Balance Sheet'!$B$4:$K$4,0))+INDEX('Balance Sheet'!$B$57:$K$57,MATCH(F$4,'Balance Sheet'!$B$4:$K$4,0)) -> 283 | G24: =INDEX('Balance Sheet'!$B$55:$K$55,MATCH(G$4,'Balance Sheet'!$B$4:$K$4,0))+INDEX('Balance Sheet'!$B$57:$K$57,MATCH(G$4,'Balance Sheet'!$B$4:$K$4,0)) -> 1411 | H24: =INDEX('Balance Sheet'!$B$55:$K$55,MATCH(H$4,'Balance Sheet'!$B$4:$K$4,0))+INDEX('Balance Sheet'!$B$57:$K$57,MATCH(H$4,'Balance Sheet'!$B$4:$K$4,0)) -> 1534 | I24: =INDEX('Balance Sheet'!$B$55:$K$55,MATCH(I$4,'Balance Sheet'!$B$4:$K$4,0))+INDEX('Balance Sheet'!$B$57:$K$57,MATCH(I$4,'Balance Sheet'!$B$4:$K$4,0)) -> 1661 | ... K24: =INDEX('Balance Sheet'!$B$55:$K$55,MATCH(K$4,'Balance Sheet'!$B$4:$K$4,0))+INDEX('Balance Sheet'!$B$57:$K$57,MATCH(K$4,'Balance Sheet'!$B$4:$K$4,0)) -> 1825
A25: Total Debt (Annual) | B25: =B23+B24 -> 604 | C25: =C23+C24 -> 200 | D25: =D23+D24 -> 679 | E25: =E23+E24 -> 622 | F25: =F23+F24 -> 439 | G25: =G23+G24 -> 1537 | H25: =H23+H24 -> 1720 | I25: =I23+I24 -> 2098 | ... K25: =K23+K24 -> 2547
A26: Net Debt (Annual) | B26: =B25-INDEX('Balance Sheet'!$B$10:$K$10,MATCH(B$4,'Balance Sheet'!$B$4:$K$4,0)) -> 430 | C26: =C25-INDEX('Balance Sheet'!$B$10:$K$10,MATCH(C$4,'Balance Sheet'!$B$4:$K$4,0)) -> 26 | D26: =D25-INDEX('Balance Sheet'!$B$10:$K$10,MATCH(D$4,'Balance Sheet'!$B$4:$K$4,0)) -> 389 | E26: =E25-INDEX('Balance Sheet'!$B$10:$K$10,MATCH(E$4,'Balance Sheet'!$B$4:$K$4,0)) -> 318 | F26: =F25-INDEX('Balance Sheet'!$B$10:$K$10,MATCH(F$4,'Balance Sheet'!$B$4:$K$4,0)) -> -108 | G26: =G25-INDEX('Balance Sheet'!$B$10:$K$10,MATCH(G$4,'Balance Sheet'!$B$4:$K$4,0)) -> 982 | H26: =H25-INDEX('Balance Sheet'!$B$10:$K$10,MATCH(H$4,'Balance Sheet'!$B$4:$K$4,0)) -> 1251 | I26: =I25-INDEX('Balance Sheet'!$B$10:$K$10,MATCH(I$4,'Balance Sheet'!$B$4:$K$4,0)) -> 1560 | ... K26: =K25-INDEX('Balance Sheet'!$B$10:$K$10,MATCH(K$4,'Balance Sheet'!$B$4:$K$4,0)) -> 1028
A27: Working Capital (Annual) | B27: =INDEX('Balance Sheet'!$B$22:$K$22,MATCH(B$4,'Balance Sheet'!$B$4:$K$4,0))-INDEX('Balance Sheet'!$B$50:$K$50,MATCH(B$4,'Balance Sheet'!$B$4:$K$4,0)) -> 137 | C27: =INDEX('Balance Sheet'!$B$22:$K$22,MATCH(C$4,'Balance Sheet'!$B$4:$K$4,0))-INDEX('Balance Sheet'!$B$50:$K$50,MATCH(C$4,'Balance Sheet'!$B$4:$K$4,0)) -> 377 | D27: =INDEX('Balance Sheet'!$B$22:$K$22,MATCH(D$4,'Balance Sheet'!$B$4:$K$4,0))-INDEX('Balance Sheet'!$B$50:$K$50,MATCH(D$4,'Balance Sheet'!$B$4:$K$4,0)) -> 710 | E27: =INDEX('Balance Sheet'!$B$22:$K$22,MATCH(E$4,'Balance Sheet'!$B$4:$K$4,0))-INDEX('Balance Sheet'!$B$50:$K$50,MATCH(E$4,'Balance Sheet'!$B$4:$K$4,0)) -> 657 | F27: =INDEX('Balance Sheet'!$B$22:$K$22,MATCH(F$4,'Balance Sheet'!$B$4:$K$4,0))-INDEX('Balance Sheet'!$B$50:$K$50,MATCH(F$4,'Balance Sheet'!$B$4:$K$4,0)) -> 560 | G27: =INDEX('Balance Sheet'!$B$22:$K$22,MATCH(G$4,'Balance Sheet'!$B$4:$K$4,0))-INDEX('Balance Sheet'!$B$50:$K$50,MATCH(G$4,'Balance Sheet'!$B$4:$K$4,0)) -> 672 | H27: =INDEX('Balance Sheet'!$B$22:$K$22,MATCH(H$4,'Balance Sheet'!$B$4:$K$4,0))-INDEX('Balance Sheet'!$B$50:$K$50,MATCH(H$4,'Balance Sheet'!$B$4:$K$4,0)) -> 493 | I27: =INDEX('Balance Sheet'!$B$22:$K$22,MATCH(I$4,'Balance Sheet'!$B$4:$K$4,0))-INDEX('Balance Sheet'!$B$50:$K$50,MATCH(I$4,'Balance Sheet'!$B$4:$K$4,0)) -> 373 | ... K27: =INDEX('Balance Sheet'!$B$22:$K$22,MATCH(K$4,'Balance Sheet'!$B$4:$K$4,0))-INDEX('Balance Sheet'!$B$50:$K$50,MATCH(K$4,'Balance Sheet'!$B$4:$K$4,0)) -> 707
A29: RASIO LIKUIDITAS & LEVERAGE
A30: Current Ratio (Annual) | B30: =INDEX('Balance Sheet'!$B$22:$K$22,MATCH(B$4,'Balance Sheet'!$B$4:$K$4,0))/INDEX('Balance Sheet'!$B$50:$K$50,MATCH(B$4,'Balance Sheet'!$B$4:$K$4,0)) -> 1.4521452 | C30: =INDEX('Balance Sheet'!$B$22:$K$22,MATCH(C$4,'Balance Sheet'!$B$4:$K$4,0))/INDEX('Balance Sheet'!$B$50:$K$50,MATCH(C$4,'Balance Sheet'!$B$4:$K$4,0)) -> 2.2823129 | D30: =INDEX('Balance Sheet'!$B$22:$K$22,MATCH(D$4,'Balance Sheet'!$B$4:$K$4,0))/INDEX('Balance Sheet'!$B$50:$K$50,MATCH(D$4,'Balance Sheet'!$B$4:$K$4,0)) -> 3.751938 | E30: =INDEX('Balance Sheet'!$B$22:$K$22,MATCH(E$4,'Balance Sheet'!$B$4:$K$4,0))/INDEX('Balance Sheet'!$B$50:$K$50,MATCH(E$4,'Balance Sheet'!$B$4:$K$4,0)) -> 3.0091743 | F30: =INDEX('Balance Sheet'!$B$22:$K$22,MATCH(F$4,'Balance Sheet'!$B$4:$K$4,0))/INDEX('Balance Sheet'!$B$50:$K$50,MATCH(F$4,'Balance Sheet'!$B$4:$K$4,0)) -> 2.8181818 | G30: =INDEX('Balance Sheet'!$B$22:$K$22,MATCH(G$4,'Balance Sheet'!$B$4:$K$4,0))/INDEX('Balance Sheet'!$B$50:$K$50,MATCH(G$4,'Balance Sheet'!$B$4:$K$4,0)) -> 3.3914591 | H30: =INDEX('Balance Sheet'!$B$22:$K$22,MATCH(H$4,'Balance Sheet'!$B$4:$K$4,0))/INDEX('Balance Sheet'!$B$50:$K$50,MATCH(H$4,'Balance Sheet'!$B$4:$K$4,0)) -> 2.1710214 | I30: =INDEX('Balance Sheet'!$B$22:$K$22,MATCH(I$4,'Balance Sheet'!$B$4:$K$4,0))/INDEX('Balance Sheet'!$B$50:$K$50,MATCH(I$4,'Balance Sheet'!$B$4:$K$4,0)) -> 1.4287356 | ... K30: =INDEX('Balance Sheet'!$B$22:$K$22,MATCH(K$4,'Balance Sheet'!$B$4:$K$4,0))/INDEX('Balance Sheet'!$B$50:$K$50,MATCH(K$4,'Balance Sheet'!$B$4:$K$4,0)) -> 1.4435383
A31: Quick Ratio (Annual) | B31: =(INDEX('Balance Sheet'!$B$22:$K$22,MATCH(B$4,'Balance Sheet'!$B$4:$K$4,0))-INDEX('Balance Sheet'!$B$19:$K$19,MATCH(B$4,'Balance Sheet'!$B$4:$K$4,0)))/INDEX('Balance Sheet'!$B$50:$K$50,MATCH(B$4,'Balance Sheet'!$B$4:$K$4,0)) -> 1.2805281 | C31: =(INDEX('Balance Sheet'!$B$22:$K$22,MATCH(C$4,'Balance Sheet'!$B$4:$K$4,0))-INDEX('Balance Sheet'!$B$19:$K$19,MATCH(C$4,'Balance Sheet'!$B$4:$K$4,0)))/INDEX('Balance Sheet'!$B$50:$K$50,MATCH(C$4,'Balance Sheet'!$B$4:$K$4,0)) -> 1.9455782 | D31: =(INDEX('Balance Sheet'!$B$22:$K$22,MATCH(D$4,'Balance Sheet'!$B$4:$K$4,0))-INDEX('Balance Sheet'!$B$19:$K$19,MATCH(D$4,'Balance Sheet'!$B$4:$K$4,0)))/INDEX('Balance Sheet'!$B$50:$K$50,MATCH(D$4,'Balance Sheet'!$B$4:$K$4,0)) -> 3.744186 | E31: =(INDEX('Balance Sheet'!$B$22:$K$22,MATCH(E$4,'Balance Sheet'!$B$4:$K$4,0))-INDEX('Balance Sheet'!$B$19:$K$19,MATCH(E$4,'Balance Sheet'!$B$4:$K$4,0)))/INDEX('Balance Sheet'!$B$50:$K$50,MATCH(E$4,'Balance Sheet'!$B$4:$K$4,0)) -> 3.0030581 | F31: =(INDEX('Balance Sheet'!$B$22:$K$22,MATCH(F$4,'Balance Sheet'!$B$4:$K$4,0))-INDEX('Balance Sheet'!$B$19:$K$19,MATCH(F$4,'Balance Sheet'!$B$4:$K$4,0)))/INDEX('Balance Sheet'!$B$50:$K$50,MATCH(F$4,'Balance Sheet'!$B$4:$K$4,0)) -> 2.8051948 | G31: =(INDEX('Balance Sheet'!$B$22:$K$22,MATCH(G$4,'Balance Sheet'!$B$4:$K$4,0))-INDEX('Balance Sheet'!$B$19:$K$19,MATCH(G$4,'Balance Sheet'!$B$4:$K$4,0)))/INDEX('Balance Sheet'!$B$50:$K$50,MATCH(G$4,'Balance Sheet'!$B$4:$K$4,0)) -> 3.366548 | H31: =(INDEX('Balance Sheet'!$B$22:$K$22,MATCH(H$4,'Balance Sheet'!$B$4:$K$4,0))-INDEX('Balance Sheet'!$B$19:$K$19,MATCH(H$4,'Balance Sheet'!$B$4:$K$4,0)))/INDEX('Balance Sheet'!$B$50:$K$50,MATCH(H$4,'Balance Sheet'!$B$4:$K$4,0)) -> 2.1425178 | I31: =(INDEX('Balance Sheet'!$B$22:$K$22,MATCH(I$4,'Balance Sheet'!$B$4:$K$4,0))-INDEX('Balance Sheet'!$B$19:$K$19,MATCH(I$4,'Balance Sheet'!$B$4:$K$4,0)))/INDEX('Balance Sheet'!$B$50:$K$50,MATCH(I$4,'Balance Sheet'!$B$4:$K$4,0)) -> 1.416092 | ... K31: =(INDEX('Balance Sheet'!$B$22:$K$22,MATCH(K$4,'Balance Sheet'!$B$4:$K$4,0))-INDEX('Balance Sheet'!$B$19:$K$19,MATCH(K$4,'Balance Sheet'!$B$4:$K$4,0)))/INDEX('Balance Sheet'!$B$50:$K$50,MATCH(K$4,'Balance Sheet'!$B$4:$K$4,0)) -> 1.4366374
A32: Debt to Equity Ratio (Annual) | B32: =B25/(INDEX('Balance Sheet'!$B$77:$K$77,MATCH(B$4,'Balance Sheet'!$B$4:$K$4,0))-INDEX('Balance Sheet'!$B$75:$K$75,MATCH(B$4,'Balance Sheet'!$B$4:$K$4,0))) -> 0.65226782 | C32: =C25/(INDEX('Balance Sheet'!$B$77:$K$77,MATCH(C$4,'Balance Sheet'!$B$4:$K$4,0))-INDEX('Balance Sheet'!$B$75:$K$75,MATCH(C$4,'Balance Sheet'!$B$4:$K$4,0))) -> 0.18604651 | D32: =D25/(INDEX('Balance Sheet'!$B$77:$K$77,MATCH(D$4,'Balance Sheet'!$B$4:$K$4,0))-INDEX('Balance Sheet'!$B$75:$K$75,MATCH(D$4,'Balance Sheet'!$B$4:$K$4,0))) -> 0.51091046 | E32: =E25/(INDEX('Balance Sheet'!$B$77:$K$77,MATCH(E$4,'Balance Sheet'!$B$4:$K$4,0))-INDEX('Balance Sheet'!$B$75:$K$75,MATCH(E$4,'Balance Sheet'!$B$4:$K$4,0))) -> 0.44207534 | F32: =F25/(INDEX('Balance Sheet'!$B$77:$K$77,MATCH(F$4,'Balance Sheet'!$B$4:$K$4,0))-INDEX('Balance Sheet'!$B$75:$K$75,MATCH(F$4,'Balance Sheet'!$B$4:$K$4,0))) -> 0.30850316 | G32: =G25/(INDEX('Balance Sheet'!$B$77:$K$77,MATCH(G$4,'Balance Sheet'!$B$4:$K$4,0))-INDEX('Balance Sheet'!$B$75:$K$75,MATCH(G$4,'Balance Sheet'!$B$4:$K$4,0))) -> 1.0578114 | H32: =H25/(INDEX('Balance Sheet'!$B$77:$K$77,MATCH(H$4,'Balance Sheet'!$B$4:$K$4,0))-INDEX('Balance Sheet'!$B$75:$K$75,MATCH(H$4,'Balance Sheet'!$B$4:$K$4,0))) -> 1.0153483 | I32: =I25/(INDEX('Balance Sheet'!$B$77:$K$77,MATCH(I$4,'Balance Sheet'!$B$4:$K$4,0))-INDEX('Balance Sheet'!$B$75:$K$75,MATCH(I$4,'Balance Sheet'!$B$4:$K$4,0))) -> 1.0484758 | ... K32: =K25/(INDEX('Balance Sheet'!$B$77:$K$77,MATCH(K$4,'Balance Sheet'!$B$4:$K$4,0))-INDEX('Balance Sheet'!$B$75:$K$75,MATCH(K$4,'Balance Sheet'!$B$4:$K$4,0))) -> 0.71484704
A33: Financial Leverage (Annual) | B33: =INDEX('Balance Sheet'!$B$26:$K$26,MATCH(B$4,'Balance Sheet'!$B$4:$K$4,0))/(INDEX('Balance Sheet'!$B$77:$K$77,MATCH(B$4,'Balance Sheet'!$B$4:$K$4,0))-INDEX('Balance Sheet'!$B$75:$K$75,MATCH(B$4,'Balance Sheet'!$B$4:$K$4,0))) -> 2.1069114 | C33: =INDEX('Balance Sheet'!$B$26:$K$26,MATCH(C$4,'Balance Sheet'!$B$4:$K$4,0))/(INDEX('Balance Sheet'!$B$77:$K$77,MATCH(C$4,'Balance Sheet'!$B$4:$K$4,0))-INDEX('Balance Sheet'!$B$75:$K$75,MATCH(C$4,'Balance Sheet'!$B$4:$K$4,0))) -> 1.8967442 | D33: =INDEX('Balance Sheet'!$B$26:$K$26,MATCH(D$4,'Balance Sheet'!$B$4:$K$4,0))/(INDEX('Balance Sheet'!$B$77:$K$77,MATCH(D$4,'Balance Sheet'!$B$4:$K$4,0))-INDEX('Balance Sheet'!$B$75:$K$75,MATCH(D$4,'Balance Sheet'!$B$4:$K$4,0))) -> 2.0820166 | E33: =INDEX('Balance Sheet'!$B$26:$K$26,MATCH(E$4,'Balance Sheet'!$B$4:$K$4,0))/(INDEX('Balance Sheet'!$B$77:$K$77,MATCH(E$4,'Balance Sheet'!$B$4:$K$4,0))-INDEX('Balance Sheet'!$B$75:$K$75,MATCH(E$4,'Balance Sheet'!$B$4:$K$4,0))) -> 1.782516 | F33: =INDEX('Balance Sheet'!$B$26:$K$26,MATCH(F$4,'Balance Sheet'!$B$4:$K$4,0))/(INDEX('Balance Sheet'!$B$77:$K$77,MATCH(F$4,'Balance Sheet'!$B$4:$K$4,0))-INDEX('Balance Sheet'!$B$75:$K$75,MATCH(F$4,'Balance Sheet'!$B$4:$K$4,0))) -> 1.6521434 | G33: =INDEX('Balance Sheet'!$B$26:$K$26,MATCH(G$4,'Balance Sheet'!$B$4:$K$4,0))/(INDEX('Balance Sheet'!$B$77:$K$77,MATCH(G$4,'Balance Sheet'!$B$4:$K$4,0))-INDEX('Balance Sheet'!$B$75:$K$75,MATCH(G$4,'Balance Sheet'!$B$4:$K$4,0))) -> 2.4129387 | H33: =INDEX('Balance Sheet'!$B$26:$K$26,MATCH(H$4,'Balance Sheet'!$B$4:$K$4,0))/(INDEX('Balance Sheet'!$B$77:$K$77,MATCH(H$4,'Balance Sheet'!$B$4:$K$4,0))-INDEX('Balance Sheet'!$B$75:$K$75,MATCH(H$4,'Balance Sheet'!$B$4:$K$4,0))) -> 2.3978749 | I33: =INDEX('Balance Sheet'!$B$26:$K$26,MATCH(I$4,'Balance Sheet'!$B$4:$K$4,0))/(INDEX('Balance Sheet'!$B$77:$K$77,MATCH(I$4,'Balance Sheet'!$B$4:$K$4,0))-INDEX('Balance Sheet'!$B$75:$K$75,MATCH(I$4,'Balance Sheet'!$B$4:$K$4,0))) -> 2.5357321 | ... K33: =INDEX('Balance Sheet'!$B$26:$K$26,MATCH(K$4,'Balance Sheet'!$B$4:$K$4,0))/(INDEX('Balance Sheet'!$B$77:$K$77,MATCH(K$4,'Balance Sheet'!$B$4:$K$4,0))-INDEX('Balance Sheet'!$B$75:$K$75,MATCH(K$4,'Balance Sheet'!$B$4:$K$4,0))) -> 2.2413696
A34: LT Debt/Equity (Annual) | B34: =B24/(INDEX('Balance Sheet'!$B$77:$K$77,MATCH(B$4,'Balance Sheet'!$B$4:$K$4,0))-INDEX('Balance Sheet'!$B$75:$K$75,MATCH(B$4,'Balance Sheet'!$B$4:$K$4,0))) -> 0.42764579 | C34: =C24/(INDEX('Balance Sheet'!$B$77:$K$77,MATCH(C$4,'Balance Sheet'!$B$4:$K$4,0))-INDEX('Balance Sheet'!$B$75:$K$75,MATCH(C$4,'Balance Sheet'!$B$4:$K$4,0))) -> 0.089302326 | D34: =D24/(INDEX('Balance Sheet'!$B$77:$K$77,MATCH(D$4,'Balance Sheet'!$B$4:$K$4,0))-INDEX('Balance Sheet'!$B$75:$K$75,MATCH(D$4,'Balance Sheet'!$B$4:$K$4,0))) -> 0.43792325 | E34: =E24/(INDEX('Balance Sheet'!$B$77:$K$77,MATCH(E$4,'Balance Sheet'!$B$4:$K$4,0))-INDEX('Balance Sheet'!$B$75:$K$75,MATCH(E$4,'Balance Sheet'!$B$4:$K$4,0))) -> 0.32267235 | F34: =F24/(INDEX('Balance Sheet'!$B$77:$K$77,MATCH(F$4,'Balance Sheet'!$B$4:$K$4,0))-INDEX('Balance Sheet'!$B$75:$K$75,MATCH(F$4,'Balance Sheet'!$B$4:$K$4,0))) -> 0.19887561 | G34: =G24/(INDEX('Balance Sheet'!$B$77:$K$77,MATCH(G$4,'Balance Sheet'!$B$4:$K$4,0))-INDEX('Balance Sheet'!$B$75:$K$75,MATCH(G$4,'Balance Sheet'!$B$4:$K$4,0))) -> 0.97109429 | H34: =H24/(INDEX('Balance Sheet'!$B$77:$K$77,MATCH(H$4,'Balance Sheet'!$B$4:$K$4,0))-INDEX('Balance Sheet'!$B$75:$K$75,MATCH(H$4,'Balance Sheet'!$B$4:$K$4,0))) -> 0.905549 | I34: =I24/(INDEX('Balance Sheet'!$B$77:$K$77,MATCH(I$4,'Balance Sheet'!$B$4:$K$4,0))-INDEX('Balance Sheet'!$B$75:$K$75,MATCH(I$4,'Balance Sheet'!$B$4:$K$4,0))) -> 0.83008496 | ... K34: =K24/(INDEX('Balance Sheet'!$B$77:$K$77,MATCH(K$4,'Balance Sheet'!$B$4:$K$4,0))-INDEX('Balance Sheet'!$B$75:$K$75,MATCH(K$4,'Balance Sheet'!$B$4:$K$4,0))) -> 0.51220881
A35: LT Debt/Total Assets (Annual) | B35: =B24/INDEX('Balance Sheet'!$B$26:$K$26,MATCH(B$4,'Balance Sheet'!$B$4:$K$4,0)) -> 0.20297283 | C35: =C24/INDEX('Balance Sheet'!$B$26:$K$26,MATCH(C$4,'Balance Sheet'!$B$4:$K$4,0)) -> 0.047081903 | D35: =D24/INDEX('Balance Sheet'!$B$26:$K$26,MATCH(D$4,'Balance Sheet'!$B$4:$K$4,0)) -> 0.2103361 | E35: =E24/INDEX('Balance Sheet'!$B$26:$K$26,MATCH(E$4,'Balance Sheet'!$B$4:$K$4,0)) -> 0.18102073 | F35: =F24/INDEX('Balance Sheet'!$B$26:$K$26,MATCH(F$4,'Balance Sheet'!$B$4:$K$4,0)) -> 0.12037431 | G35: =G24/INDEX('Balance Sheet'!$B$26:$K$26,MATCH(G$4,'Balance Sheet'!$B$4:$K$4,0)) -> 0.40245294 | H35: =H24/INDEX('Balance Sheet'!$B$26:$K$26,MATCH(H$4,'Balance Sheet'!$B$4:$K$4,0)) -> 0.37764648 | I35: =I24/INDEX('Balance Sheet'!$B$26:$K$26,MATCH(I$4,'Balance Sheet'!$B$4:$K$4,0)) -> 0.32735514 | ... K35: =K24/INDEX('Balance Sheet'!$B$26:$K$26,MATCH(K$4,'Balance Sheet'!$B$4:$K$4,0)) -> 0.22852492
A36: Net Debt/Total Equity (Annual) | B36: =B26/(INDEX('Balance Sheet'!$B$77:$K$77,MATCH(B$4,'Balance Sheet'!$B$4:$K$4,0))-INDEX('Balance Sheet'!$B$75:$K$75,MATCH(B$4,'Balance Sheet'!$B$4:$K$4,0))) -> 0.46436285 | C36: =C26/(INDEX('Balance Sheet'!$B$77:$K$77,MATCH(C$4,'Balance Sheet'!$B$4:$K$4,0))-INDEX('Balance Sheet'!$B$75:$K$75,MATCH(C$4,'Balance Sheet'!$B$4:$K$4,0))) -> 0.024186047 | D36: =D26/(INDEX('Balance Sheet'!$B$77:$K$77,MATCH(D$4,'Balance Sheet'!$B$4:$K$4,0))-INDEX('Balance Sheet'!$B$75:$K$75,MATCH(D$4,'Balance Sheet'!$B$4:$K$4,0))) -> 0.29270128 | E36: =E26/(INDEX('Balance Sheet'!$B$77:$K$77,MATCH(E$4,'Balance Sheet'!$B$4:$K$4,0))-INDEX('Balance Sheet'!$B$75:$K$75,MATCH(E$4,'Balance Sheet'!$B$4:$K$4,0))) -> 0.22601279 | F36: =F26/(INDEX('Balance Sheet'!$B$77:$K$77,MATCH(F$4,'Balance Sheet'!$B$4:$K$4,0))-INDEX('Balance Sheet'!$B$75:$K$75,MATCH(F$4,'Balance Sheet'!$B$4:$K$4,0))) -> -0.075895994 | G36: =G26/(INDEX('Balance Sheet'!$B$77:$K$77,MATCH(G$4,'Balance Sheet'!$B$4:$K$4,0))-INDEX('Balance Sheet'!$B$75:$K$75,MATCH(G$4,'Balance Sheet'!$B$4:$K$4,0))) -> 0.67584308 | H36: =H26/(INDEX('Balance Sheet'!$B$77:$K$77,MATCH(H$4,'Balance Sheet'!$B$4:$K$4,0))-INDEX('Balance Sheet'!$B$75:$K$75,MATCH(H$4,'Balance Sheet'!$B$4:$K$4,0))) -> 0.73848878 | I36: =I26/(INDEX('Balance Sheet'!$B$77:$K$77,MATCH(I$4,'Balance Sheet'!$B$4:$K$4,0))-INDEX('Balance Sheet'!$B$75:$K$75,MATCH(I$4,'Balance Sheet'!$B$4:$K$4,0))) -> 0.77961019 | ... K36: =K26/(INDEX('Balance Sheet'!$B$77:$K$77,MATCH(K$4,'Balance Sheet'!$B$4:$K$4,0))-INDEX('Balance Sheet'!$B$75:$K$75,MATCH(K$4,'Balance Sheet'!$B$4:$K$4,0))) -> 0.28852091
A37: Total Debt/Total Assets (Annual) | B37: =B25/INDEX('Balance Sheet'!$B$26:$K$26,MATCH(B$4,'Balance Sheet'!$B$4:$K$4,0)) -> 0.30958483 | C37: =C25/INDEX('Balance Sheet'!$B$26:$K$26,MATCH(C$4,'Balance Sheet'!$B$4:$K$4,0)) -> 0.098087298 | D37: =D25/INDEX('Balance Sheet'!$B$26:$K$26,MATCH(D$4,'Balance Sheet'!$B$4:$K$4,0)) -> 0.24539212 | E37: =E25/INDEX('Balance Sheet'!$B$26:$K$26,MATCH(E$4,'Balance Sheet'!$B$4:$K$4,0)) -> 0.24800638 | F37: =F25/INDEX('Balance Sheet'!$B$26:$K$26,MATCH(F$4,'Balance Sheet'!$B$4:$K$4,0)) -> 0.18672905 | G37: =G25/INDEX('Balance Sheet'!$B$26:$K$26,MATCH(G$4,'Balance Sheet'!$B$4:$K$4,0)) -> 0.43839133 | H37: =H25/INDEX('Balance Sheet'!$B$26:$K$26,MATCH(H$4,'Balance Sheet'!$B$4:$K$4,0)) -> 0.42343673 | I37: =I25/INDEX('Balance Sheet'!$B$26:$K$26,MATCH(I$4,'Balance Sheet'!$B$4:$K$4,0)) -> 0.41348049 | ... K37: =K25/INDEX('Balance Sheet'!$B$26:$K$26,MATCH(K$4,'Balance Sheet'!$B$4:$K$4,0)) -> 0.31893313
A38: Total Liabilities/Equity (Annual) | B38: =INDEX('Balance Sheet'!$B$65:$K$65,MATCH(B$4,'Balance Sheet'!$B$4:$K$4,0))/(INDEX('Balance Sheet'!$B$77:$K$77,MATCH(B$4,'Balance Sheet'!$B$4:$K$4,0))-INDEX('Balance Sheet'!$B$75:$K$75,MATCH(B$4,'Balance Sheet'!$B$4:$K$4,0))) -> 0.77969762 | C38: =INDEX('Balance Sheet'!$B$65:$K$65,MATCH(C$4,'Balance Sheet'!$B$4:$K$4,0))/(INDEX('Balance Sheet'!$B$77:$K$77,MATCH(C$4,'Balance Sheet'!$B$4:$K$4,0))-INDEX('Balance Sheet'!$B$75:$K$75,MATCH(C$4,'Balance Sheet'!$B$4:$K$4,0))) -> 0.38139535 | D38: =INDEX('Balance Sheet'!$B$65:$K$65,MATCH(D$4,'Balance Sheet'!$B$4:$K$4,0))/(INDEX('Balance Sheet'!$B$77:$K$77,MATCH(D$4,'Balance Sheet'!$B$4:$K$4,0))-INDEX('Balance Sheet'!$B$75:$K$75,MATCH(D$4,'Balance Sheet'!$B$4:$K$4,0))) -> 0.64635064 | E38: =INDEX('Balance Sheet'!$B$65:$K$65,MATCH(E$4,'Balance Sheet'!$B$4:$K$4,0))/(INDEX('Balance Sheet'!$B$77:$K$77,MATCH(E$4,'Balance Sheet'!$B$4:$K$4,0))-INDEX('Balance Sheet'!$B$75:$K$75,MATCH(E$4,'Balance Sheet'!$B$4:$K$4,0))) -> 0.57071784 | F38: =INDEX('Balance Sheet'!$B$65:$K$65,MATCH(F$4,'Balance Sheet'!$B$4:$K$4,0))/(INDEX('Balance Sheet'!$B$77:$K$77,MATCH(F$4,'Balance Sheet'!$B$4:$K$4,0))-INDEX('Balance Sheet'!$B$75:$K$75,MATCH(F$4,'Balance Sheet'!$B$4:$K$4,0))) -> 0.4300773 | G38: =INDEX('Balance Sheet'!$B$65:$K$65,MATCH(G$4,'Balance Sheet'!$B$4:$K$4,0))/(INDEX('Balance Sheet'!$B$77:$K$77,MATCH(G$4,'Balance Sheet'!$B$4:$K$4,0))-INDEX('Balance Sheet'!$B$75:$K$75,MATCH(G$4,'Balance Sheet'!$B$4:$K$4,0))) -> 1.1837577 | H38: =INDEX('Balance Sheet'!$B$65:$K$65,MATCH(H$4,'Balance Sheet'!$B$4:$K$4,0))/(INDEX('Balance Sheet'!$B$77:$K$77,MATCH(H$4,'Balance Sheet'!$B$4:$K$4,0))-INDEX('Balance Sheet'!$B$75:$K$75,MATCH(H$4,'Balance Sheet'!$B$4:$K$4,0))) -> 1.1729634 | I38: =INDEX('Balance Sheet'!$B$65:$K$65,MATCH(I$4,'Balance Sheet'!$B$4:$K$4,0))/(INDEX('Balance Sheet'!$B$77:$K$77,MATCH(I$4,'Balance Sheet'!$B$4:$K$4,0))-INDEX('Balance Sheet'!$B$75:$K$75,MATCH(I$4,'Balance Sheet'!$B$4:$K$4,0))) -> 1.3433283 | ... K38: =INDEX('Balance Sheet'!$B$65:$K$65,MATCH(K$4,'Balance Sheet'!$B$4:$K$4,0))/(INDEX('Balance Sheet'!$B$77:$K$77,MATCH(K$4,'Balance Sheet'!$B$4:$K$4,0))-INDEX('Balance Sheet'!$B$75:$K$75,MATCH(K$4,'Balance Sheet'!$B$4:$K$4,0))) -> 1.0404154
A40: RASIO EFISIENSI (ACTIVITY)
A41: Days Sales Outstanding (Annual) | B41: =(INDEX('Balance Sheet'!$B$14:$K$14,MATCH(B$4,'Balance Sheet'!$B$4:$K$4,0))/INDEX('Income Statement'!$B$5:$K$5,MATCH(B$4,'Income Statement'!$B$4:$K$4,0)))*365 -> 18.345396 | C41: =(AVERAGE(INDEX('Balance Sheet'!$B$14:$K$14,MATCH(C$4,'Balance Sheet'!$B$4:$K$4,0)),INDEX('Balance Sheet'!$B$14:$K$14,MATCH(B$4,'Balance Sheet'!$B$4:$K$4,0)))/INDEX('Income Statement'!$B$5:$K$5,MATCH(C$4,'Income Statement'!$B$4:$K$4,0)))*365 -> 35.437782 | D41: =(AVERAGE(INDEX('Balance Sheet'!$B$14:$K$14,MATCH(D$4,'Balance Sheet'!$B$4:$K$4,0)),INDEX('Balance Sheet'!$B$14:$K$14,MATCH(C$4,'Balance Sheet'!$B$4:$K$4,0)))/INDEX('Income Statement'!$B$5:$K$5,MATCH(D$4,'Income Statement'!$B$4:$K$4,0)))*365 -> 50.8571 | E41: =(AVERAGE(INDEX('Balance Sheet'!$B$14:$K$14,MATCH(E$4,'Balance Sheet'!$B$4:$K$4,0)),INDEX('Balance Sheet'!$B$14:$K$14,MATCH(D$4,'Balance Sheet'!$B$4:$K$4,0)))/INDEX('Income Statement'!$B$5:$K$5,MATCH(E$4,'Income Statement'!$B$4:$K$4,0)))*365 -> 44.463252 | F41: =(AVERAGE(INDEX('Balance Sheet'!$B$14:$K$14,MATCH(F$4,'Balance Sheet'!$B$4:$K$4,0)),INDEX('Balance Sheet'!$B$14:$K$14,MATCH(E$4,'Balance Sheet'!$B$4:$K$4,0)))/INDEX('Income Statement'!$B$5:$K$5,MATCH(F$4,'Income Statement'!$B$4:$K$4,0)))*365 -> 46.131944 | G41: =(AVERAGE(INDEX('Balance Sheet'!$B$14:$K$14,MATCH(G$4,'Balance Sheet'!$B$4:$K$4,0)),INDEX('Balance Sheet'!$B$14:$K$14,MATCH(F$4,'Balance Sheet'!$B$4:$K$4,0)))/INDEX('Income Statement'!$B$5:$K$5,MATCH(G$4,'Income Statement'!$B$4:$K$4,0)))*365 -> 42.215302 | H41: =(AVERAGE(INDEX('Balance Sheet'!$B$14:$K$14,MATCH(H$4,'Balance Sheet'!$B$4:$K$4,0)),INDEX('Balance Sheet'!$B$14:$K$14,MATCH(G$4,'Balance Sheet'!$B$4:$K$4,0)))/INDEX('Income Statement'!$B$5:$K$5,MATCH(H$4,'Income Statement'!$B$4:$K$4,0)))*365 -> 41.6313 | I41: =(AVERAGE(INDEX('Balance Sheet'!$B$14:$K$14,MATCH(I$4,'Balance Sheet'!$B$4:$K$4,0)),INDEX('Balance Sheet'!$B$14:$K$14,MATCH(H$4,'Balance Sheet'!$B$4:$K$4,0)))/INDEX('Income Statement'!$B$5:$K$5,MATCH(I$4,'Income Statement'!$B$4:$K$4,0)))*365 -> 42.630309 | J41: =(AVERAGE(INDEX('Balance Sheet'!$B$14:$K$14,MATCH(J$4,'Balance Sheet'!$B$4:$K$4,0)),INDEX('Balance Sheet'!$B$14:$K$14,MATCH(I$4,'Balance Sheet'!$B$4:$K$4,0)))/INDEX('Income Statement'!$B$5:$K$5,MATCH(J$4,'Income Statement'!$B$4:$K$4,0)))*365 -> 45.839945 | K41: =(AVERAGE(INDEX('Balance Sheet'!$B$14:$K$14,MATCH(K$4,'Balance Sheet'!$B$4:$K$4,0)),INDEX('Balance Sheet'!$B$14:$K$14,MATCH(J$4,'Balance Sheet'!$B$4:$K$4,0)))/INDEX('Income Statement'!$B$5:$K$5,MATCH(K$4,'Income Statement'!$B$4:$K$4,0)))*365 -> 45.396563
A42: Days Inventory (Annual) | B42: =(INDEX('Balance Sheet'!$B$19:$K$19,MATCH(B$4,'Balance Sheet'!$B$4:$K$4,0))/ABS(INDEX('Income Statement'!$B$6:$K$6,MATCH(B$4,'Income Statement'!$B$4:$K$4,0))))*365 -> 8.7667436 | C42: =(AVERAGE(INDEX('Balance Sheet'!$B$19:$K$19,MATCH(C$4,'Balance Sheet'!$B$4:$K$4,0)),INDEX('Balance Sheet'!$B$19:$K$19,MATCH(B$4,'Balance Sheet'!$B$4:$K$4,0)))/ABS(INDEX('Income Statement'!$B$6:$K$6,MATCH(C$4,'Income Statement'!$B$4:$K$4,0))))*365 -> 16.551051 | D42: =(AVERAGE(INDEX('Balance Sheet'!$B$19:$K$19,MATCH(D$4,'Balance Sheet'!$B$4:$K$4,0)),INDEX('Balance Sheet'!$B$19:$K$19,MATCH(C$4,'Balance Sheet'!$B$4:$K$4,0)))/ABS(INDEX('Income Statement'!$B$6:$K$6,MATCH(D$4,'Income Statement'!$B$4:$K$4,0))))*365 -> 13.251258 | E42: =(AVERAGE(INDEX('Balance Sheet'!$B$19:$K$19,MATCH(E$4,'Balance Sheet'!$B$4:$K$4,0)),INDEX('Balance Sheet'!$B$19:$K$19,MATCH(D$4,'Balance Sheet'!$B$4:$K$4,0)))/ABS(INDEX('Income Statement'!$B$6:$K$6,MATCH(E$4,'Income Statement'!$B$4:$K$4,0))))*365 -> 0.49125168 | F42: =(AVERAGE(INDEX('Balance Sheet'!$B$19:$K$19,MATCH(F$4,'Balance Sheet'!$B$4:$K$4,0)),INDEX('Balance Sheet'!$B$19:$K$19,MATCH(E$4,'Balance Sheet'!$B$4:$K$4,0)))/ABS(INDEX('Income Statement'!$B$6:$K$6,MATCH(F$4,'Income Statement'!$B$4:$K$4,0))))*365 -> 0.90871369 | G42: =(AVERAGE(INDEX('Balance Sheet'!$B$19:$K$19,MATCH(G$4,'Balance Sheet'!$B$4:$K$4,0)),INDEX('Balance Sheet'!$B$19:$K$19,MATCH(F$4,'Balance Sheet'!$B$4:$K$4,0)))/ABS(INDEX('Income Statement'!$B$6:$K$6,MATCH(G$4,'Income Statement'!$B$4:$K$4,0))))*365 -> 1.6955236 | H42: =(AVERAGE(INDEX('Balance Sheet'!$B$19:$K$19,MATCH(H$4,'Balance Sheet'!$B$4:$K$4,0)),INDEX('Balance Sheet'!$B$19:$K$19,MATCH(G$4,'Balance Sheet'!$B$4:$K$4,0)))/ABS(INDEX('Income Statement'!$B$6:$K$6,MATCH(H$4,'Income Statement'!$B$4:$K$4,0))))*365 -> 2.2933201 | I42: =(AVERAGE(INDEX('Balance Sheet'!$B$19:$K$19,MATCH(I$4,'Balance Sheet'!$B$4:$K$4,0)),INDEX('Balance Sheet'!$B$19:$K$19,MATCH(H$4,'Balance Sheet'!$B$4:$K$4,0)))/ABS(INDEX('Income Statement'!$B$6:$K$6,MATCH(I$4,'Income Statement'!$B$4:$K$4,0))))*365 -> 1.9969077 | J42: =(AVERAGE(INDEX('Balance Sheet'!$B$19:$K$19,MATCH(J$4,'Balance Sheet'!$B$4:$K$4,0)),INDEX('Balance Sheet'!$B$19:$K$19,MATCH(I$4,'Balance Sheet'!$B$4:$K$4,0)))/ABS(INDEX('Income Statement'!$B$6:$K$6,MATCH(J$4,'Income Statement'!$B$4:$K$4,0))))*365 -> 1.243188 | K42: =(AVERAGE(INDEX('Balance Sheet'!$B$19:$K$19,MATCH(K$4,'Balance Sheet'!$B$4:$K$4,0)),INDEX('Balance Sheet'!$B$19:$K$19,MATCH(J$4,'Balance Sheet'!$B$4:$K$4,0)))/ABS(INDEX('Income Statement'!$B$6:$K$6,MATCH(K$4,'Income Statement'!$B$4:$K$4,0))))*365 -> 1.1388456
A43: Payables Period (Annual) | B43: =(INDEX('Balance Sheet'!$B$35:$K$35,MATCH(B$4,'Balance Sheet'!$B$4:$K$4,0))/ABS(INDEX('Income Statement'!$B$6:$K$6,MATCH(B$4,'Income Statement'!$B$4:$K$4,0))))*365 -> 10.95843 | C43: =(AVERAGE(INDEX('Balance Sheet'!$B$35:$K$35,MATCH(C$4,'Balance Sheet'!$B$4:$K$4,0)),INDEX('Balance Sheet'!$B$35:$K$35,MATCH(B$4,'Balance Sheet'!$B$4:$K$4,0)))/ABS(INDEX('Income Statement'!$B$6:$K$6,MATCH(C$4,'Income Statement'!$B$4:$K$4,0))))*365 -> 20.606607 | D43: =(AVERAGE(INDEX('Balance Sheet'!$B$35:$K$35,MATCH(D$4,'Balance Sheet'!$B$4:$K$4,0)),INDEX('Balance Sheet'!$B$35:$K$35,MATCH(C$4,'Balance Sheet'!$B$4:$K$4,0)))/ABS(INDEX('Income Statement'!$B$6:$K$6,MATCH(D$4,'Income Statement'!$B$4:$K$4,0))))*365 -> 31.094536 | E43: =(AVERAGE(INDEX('Balance Sheet'!$B$35:$K$35,MATCH(E$4,'Balance Sheet'!$B$4:$K$4,0)),INDEX('Balance Sheet'!$B$35:$K$35,MATCH(D$4,'Balance Sheet'!$B$4:$K$4,0)))/ABS(INDEX('Income Statement'!$B$6:$K$6,MATCH(E$4,'Income Statement'!$B$4:$K$4,0))))*365 -> 29.352288 | F43: =(AVERAGE(INDEX('Balance Sheet'!$B$35:$K$35,MATCH(F$4,'Balance Sheet'!$B$4:$K$4,0)),INDEX('Balance Sheet'!$B$35:$K$35,MATCH(E$4,'Balance Sheet'!$B$4:$K$4,0)))/ABS(INDEX('Income Statement'!$B$6:$K$6,MATCH(F$4,'Income Statement'!$B$4:$K$4,0))))*365 -> 34.834025 | G43: =(AVERAGE(INDEX('Balance Sheet'!$B$35:$K$35,MATCH(G$4,'Balance Sheet'!$B$4:$K$4,0)),INDEX('Balance Sheet'!$B$35:$K$35,MATCH(F$4,'Balance Sheet'!$B$4:$K$4,0)))/ABS(INDEX('Income Statement'!$B$6:$K$6,MATCH(G$4,'Income Statement'!$B$4:$K$4,0))))*365 -> 32.985642 | H43: =(AVERAGE(INDEX('Balance Sheet'!$B$35:$K$35,MATCH(H$4,'Balance Sheet'!$B$4:$K$4,0)),INDEX('Balance Sheet'!$B$35:$K$35,MATCH(G$4,'Balance Sheet'!$B$4:$K$4,0)))/ABS(INDEX('Income Statement'!$B$6:$K$6,MATCH(H$4,'Income Statement'!$B$4:$K$4,0))))*365 -> 33.434193 | I43: =(AVERAGE(INDEX('Balance Sheet'!$B$35:$K$35,MATCH(I$4,'Balance Sheet'!$B$4:$K$4,0)),INDEX('Balance Sheet'!$B$35:$K$35,MATCH(H$4,'Balance Sheet'!$B$4:$K$4,0)))/ABS(INDEX('Income Statement'!$B$6:$K$6,MATCH(I$4,'Income Statement'!$B$4:$K$4,0))))*365 -> 40.19862 | J43: =(AVERAGE(INDEX('Balance Sheet'!$B$35:$K$35,MATCH(J$4,'Balance Sheet'!$B$4:$K$4,0)),INDEX('Balance Sheet'!$B$35:$K$35,MATCH(I$4,'Balance Sheet'!$B$4:$K$4,0)))/ABS(INDEX('Income Statement'!$B$6:$K$6,MATCH(J$4,'Income Statement'!$B$4:$K$4,0))))*365 -> 36.922684 | K43: =(AVERAGE(INDEX('Balance Sheet'!$B$35:$K$35,MATCH(K$4,'Balance Sheet'!$B$4:$K$4,0)),INDEX('Balance Sheet'!$B$35:$K$35,MATCH(J$4,'Balance Sheet'!$B$4:$K$4,0)))/ABS(INDEX('Income Statement'!$B$6:$K$6,MATCH(K$4,'Income Statement'!$B$4:$K$4,0))))*365 -> 42.080343
A44: Cash Conversion Cycle (Annual) | B44: =B41+B42-B43 -> 16.15371 | C44: =C41+C42-C43 -> 31.382227 | D44: =D41+D42-D43 -> 33.013822 | E44: =E41+E42-E43 -> 15.602216 | F44: =F41+F42-F43 -> 12.206633 | G44: =G41+G42-G43 -> 10.925184 | H44: =H41+H42-H43 -> 10.490427 | I44: =I41+I42-I43 -> 4.4285962 | ... K44: =K41+K42-K43 -> 4.4550658
A45: Receivables Turnover (Annual) | B45: =365/B41 -> 19.896 | C45: =365/C41 -> 10.299742 | D45: =365/D41 -> 7.1769723 | E45: =365/E41 -> 8.2090261 | F45: =365/F41 -> 7.9120879 | G45: =365/G41 -> 8.6461538 | H45: =365/H41 -> 8.7674419 | I45: =365/I41 -> 8.5619835 | ... K45: =365/K41 -> 8.0402562
A46: Inventory Turnover (Annual) | B46: =365/B42 -> 41.634615 | C46: =365/C42 -> 22.05298 | D46: =365/D42 -> 27.544554 | E46: =365/E42 -> 743 | F46: =365/F42 -> 401.66667 | G46: =365/G42 -> 215.27273 | H46: =365/H42 -> 159.15789 | I46: =365/I42 -> 182.78261 | ... K46: =365/K42 -> 320.5
...

Sheet Market Data
A1: MARKET DATA - PT Rukun Raharja Tbk (RAJA)
A4: Category | B4: Item | C4: Value
A5: General | B5: Company | C5: PT Rukun Raharja Tbk
A6: General | B6: Ticker | C6: RAJA
A7: General | B7: Sector | C7: Energi
A8: General | B8: Industry | C8: Minyak & Gas - Layanan Terintegrasi (Midstream/Trading Gas, Pembangkit Listrik)
A9: Market | B9: Current Price | C9: 890
A10: Market | B10: Share Outstanding (Miliar Lembar) | C10: 21.14
A11: Market | B11: Market Cap (Miliar Rp) | C11: =C9*C10 -> 18814.6
A12: Market | B12: Enterprise Value (Miliar Rp) | C12: =C11+'Key Ratio'!K25-'Balance Sheet'!K10 -> 19842.6
A13: Market | B13: Beta | C13: 2.86
A14: Market | B14: Free Float (%)
A15: Market | B15: Dividend Yield (%)
A16: Market | B16: 52 Week High
A17: Market | B17: 52 Week Low
A18: Market | B18: Average Volume
A19: Market | B19: Last Updated | C19: 1 Agustus 2026
A23: HISTORIS HARGA SAHAM & VALUASI PASAR (12M 2016 - 12M 2025)
A24: Keterangan | B24: 12M 2016 | C24: 12M 2017 | D24: 12M 2018 | E24: 12M 2019 | F24: 12M 2020 | G24: 12M 2021 | H24: 12M 2022 | I24: 12M 2023 | J24: 12M 2024 | K24: 12M 2025
A25: Harga Saham / Price (Rp) | B25: 200 | C25: 300 | D25: 325 | E25: 190 | F25: 250 | G25: 180 | H25: 1050 | I25: 1410 | J25: 2725 | K25: 6100
A26: Share Outstanding (Miliar Lembar) | B26: ='Key Ratio'!B6 -> 4.08 | C26: ='Key Ratio'!C6 -> 4.08 | D26: ='Key Ratio'!D6 -> 4.23 | E26: ='Key Ratio'!E6 -> 4.23 | F26: ='Key Ratio'!F6 -> 4.23 | G26: ='Key Ratio'!G6 -> 4.23 | H26: ='Key Ratio'!H6 -> 4.23 | I26: ='Key Ratio'!I6 -> 4.23 | ... K26: ='Key Ratio'!K6 -> 4.23
A27: Market Cap (Miliar Rp) | B27: =B25*B26 -> 816 | C27: =C25*C26 -> 1224 | D27: =D25*D26 -> 1374.75 | E27: =E25*E26 -> 803.7 | F27: =F25*F26 -> 1057.5 | G27: =G25*G26 -> 761.4 | H27: =H25*H26 -> 4441.5 | I27: =I25*I26 -> 5964.3 | ... K27: =K25*K26 -> 25803
A28: Total Debt (Miliar Rp) | B28: ='Key Ratio'!B25 -> 604 | C28: ='Key Ratio'!C25 -> 200 | D28: ='Key Ratio'!D25 -> 679 | E28: ='Key Ratio'!E25 -> 622 | F28: ='Key Ratio'!F25 -> 439 | G28: ='Key Ratio'!G25 -> 1537 | H28: ='Key Ratio'!H25 -> 1720 | I28: ='Key Ratio'!I25 -> 2098 | ... K28: ='Key Ratio'!K25 -> 2547
A29: Kas Dan Setara Kas (Miliar Rp) | B29: =INDEX('Balance Sheet'!$B$10:$K$10,MATCH(B$24,'Balance Sheet'!$B$4:$K$4,0)) -> 174 | C29: =INDEX('Balance Sheet'!$B$10:$K$10,MATCH(C$24,'Balance Sheet'!$B$4:$K$4,0)) -> 174 | D29: =INDEX('Balance Sheet'!$B$10:$K$10,MATCH(D$24,'Balance Sheet'!$B$4:$K$4,0)) -> 290 | E29: =INDEX('Balance Sheet'!$B$10:$K$10,MATCH(E$24,'Balance Sheet'!$B$4:$K$4,0)) -> 304 | F29: =INDEX('Balance Sheet'!$B$10:$K$10,MATCH(F$24,'Balance Sheet'!$B$4:$K$4,0)) -> 547 | G29: =INDEX('Balance Sheet'!$B$10:$K$10,MATCH(G$24,'Balance Sheet'!$B$4:$K$4,0)) -> 555 | H29: =INDEX('Balance Sheet'!$B$10:$K$10,MATCH(H$24,'Balance Sheet'!$B$4:$K$4,0)) -> 469 | I29: =INDEX('Balance Sheet'!$B$10:$K$10,MATCH(I$24,'Balance Sheet'!$B$4:$K$4,0)) -> 538 | ... K29: =INDEX('Balance Sheet'!$B$10:$K$10,MATCH(K$24,'Balance Sheet'!$B$4:$K$4,0)) -> 1519
A30: Enterprise Value (Miliar Rp) | B30: =B27+B28-B29 -> 1246 | C30: =C27+C28-C29 -> 1250 | D30: =D27+D28-D29 -> 1763.75 | E30: =E27+E28-E29 -> 1121.7 | F30: =F27+F28-F29 -> 949.5 | G30: =G27+G28-G29 -> 1743.4 | H30: =H27+H28-H29 -> 5692.5 | I30: =I27+I28-I29 -> 7524.3 | ... K30: =K27+K28-K29 -> 26831
A31: PE Ratio (x) | B31: =B25/'Key Ratio'!B7 -> 9.3793103 | C31: =C25/'Key Ratio'!C7 -> 7.8461538 | D31: =D25/'Key Ratio'!D7 -> 8.4340491 | E31: =E25/'Key Ratio'!E7 -> 9.9222222 | F31: =F25/'Key Ratio'!F7 -> 52.875 | G31: =G25/'Key Ratio'!G7 -> 23.79375 | H31: =H25/'Key Ratio'!H7 -> 33.90458 | I31: =I25/'Key Ratio'!I7 -> 15.253964 | ... K31: =K25/'Key Ratio'!K7 -> 57.467706
A32: Price to Sales (x) | B32: =B27/INDEX('Income Statement'!$B$5:$K$5,MATCH(B$24,'Income Statement'!$B$4:$K$4,0)) -> 0.32810615 | C32: =C27/INDEX('Income Statement'!$B$5:$K$5,MATCH(C$24,'Income Statement'!$B$4:$K$4,0)) -> 0.61414952 | D32: =D27/INDEX('Income Statement'!$B$5:$K$5,MATCH(D$24,'Income Statement'!$B$4:$K$4,0)) -> 0.81684492 | E32: =E27/INDEX('Income Statement'!$B$5:$K$5,MATCH(E$24,'Income Statement'!$B$4:$K$4,0)) -> 0.46510417 | F32: =F27/INDEX('Income Statement'!$B$5:$K$5,MATCH(F$24,'Income Statement'!$B$4:$K$4,0)) -> 0.734375 | G32: =G27/INDEX('Income Statement'!$B$5:$K$5,MATCH(G$24,'Income Statement'!$B$4:$K$4,0)) -> 0.54192171 | H32: =H27/INDEX('Income Statement'!$B$5:$K$5,MATCH(H$24,'Income Statement'!$B$4:$K$4,0)) -> 2.3562334 | I32: =I27/INDEX('Income Statement'!$B$5:$K$5,MATCH(I$24,'Income Statement'!$B$4:$K$4,0)) -> 1.9190154 | ... K32: =K27/INDEX('Income Statement'!$B$5:$K$5,MATCH(K$24,'Income Statement'!$B$4:$K$4,0)) -> 5.8723259
A33: Price to Book Value (x) | B33: =B25/'Key Ratio'!B18 -> 0.8812095 | C33: =C25/'Key Ratio'!C18 -> 1.1386047 | D33: =D25/'Key Ratio'!D18 -> 1.0344244 | E33: =E25/'Key Ratio'!E18 -> 0.57121535 | F33: =F25/'Key Ratio'!F18 -> 0.74314828 | G33: =G25/'Key Ratio'!G18 -> 0.52401927 | H33: =H25/'Key Ratio'!H18 -> 2.6219008 | I33: =I25/'Key Ratio'!I18 -> 2.9806597 | ... K33: =K25/'Key Ratio'!K18 -> 7.241931
A34: Price to Tangible Book Value (x) | B34: =B25/'Key Ratio'!B20 -> 1.2769761 | C34: =C25/'Key Ratio'!C20 -> 1.5598191 | D34: =D25/'Key Ratio'!D20 -> 1.3481561 | E34: =E25/'Key Ratio'!E20 -> 0.72466532 | F34: =F25/'Key Ratio'!F20 -> 0.94240048 | G34: =G25/'Key Ratio'!G20 -> 0.70028011 | H34: =H25/'Key Ratio'!H20 -> 3.443865 | I34: =I25/'Key Ratio'!I20 -> 3.719041 | ... K34: =K25/'Key Ratio'!K20 -> 8.2436888

Sheet Forecast
A1: FORECAST 5 TAHUN - PT Rukun Raharja Tbk (RAJA)
A4: Keterangan | B4: 12M 2026F | C4: 12M 2027F | D4: 12M 2028F | E4: 12M 2029F | F4: 12M 2030F
A5: Pertumbuhan Pendapatan (%) | B5: =B68 -> 0.21182566 | C5: =('Income Statement'!$K$5/'Income Statement'!$H$5)^(1/3)-1 -> 0.32591668 | D5: =('Income Statement'!$K$5/'Income Statement'!$H$5)^(1/3)-1 -> 0.32591668 | E5: =('Income Statement'!$K$5/'Income Statement'!$H$5)^(1/3)-1 -> 0.32591668 | F5: =('Income Statement'!$K$5/'Income Statement'!$H$5)^(1/3)-1 -> 0.32591668
A6: Margin Laba Kotor (%) | B6: =AVERAGE('Income Statement'!$I$7/'Income Statement'!$I$5,'Income Statement'!$J$7/'Income Statement'!$J$5,'Income Statement'!$K$7/'Income Statement'!$K$5) -> 0.28876101 | C6: =AVERAGE('Income Statement'!$I$7/'Income Statement'!$I$5,'Income Statement'!$J$7/'Income Statement'!$J$5,'Income Statement'!$K$7/'Income Statement'!$K$5) -> 0.28876101 | D6: =AVERAGE('Income Statement'!$I$7/'Income Statement'!$I$5,'Income Statement'!$J$7/'Income Statement'!$J$5,'Income Statement'!$K$7/'Income Statement'!$K$5) -> 0.28876101 | E6: =AVERAGE('Income Statement'!$I$7/'Income Statement'!$I$5,'Income Statement'!$J$7/'Income Statement'!$J$5,'Income Statement'!$K$7/'Income Statement'!$K$5) -> 0.28876101 | F6: =AVERAGE('Income Statement'!$I$7/'Income Statement'!$I$5,'Income Statement'!$J$7/'Income Statement'!$J$5,'Income Statement'!$K$7/'Income Statement'!$K$5) -> 0.28876101
A7: Beban Usaha (% Pendapatan) | B7: =AVERAGE(ABS('Income Statement'!$I$8)/'Income Statement'!$I$5,ABS('Income Statement'!$J$8)/'Income Statement'!$J$5,ABS('Income Statement'!$K$8)/'Income Statement'!$K$5) -> 0.086948535 | C7: =AVERAGE(ABS('Income Statement'!$I$8)/'Income Statement'!$I$5,ABS('Income Statement'!$J$8)/'Income Statement'!$J$5,ABS('Income Statement'!$K$8)/'Income Statement'!$K$5) -> 0.086948535 | D7: =AVERAGE(ABS('Income Statement'!$I$8)/'Income Statement'!$I$5,ABS('Income Statement'!$J$8)/'Income Statement'!$J$5,ABS('Income Statement'!$K$8)/'Income Statement'!$K$5) -> 0.086948535 | E7: =AVERAGE(ABS('Income Statement'!$I$8)/'Income Statement'!$I$5,ABS('Income Statement'!$J$8)/'Income Statement'!$J$5,ABS('Income Statement'!$K$8)/'Income Statement'!$K$5) -> 0.086948535 | F7: =AVERAGE(ABS('Income Statement'!$I$8)/'Income Statement'!$I$5,ABS('Income Statement'!$J$8)/'Income Statement'!$J$5,ABS('Income Statement'!$K$8)/'Income Statement'!$K$5) -> 0.086948535
A8: Pertumbuhan Bagian Atas Hasil Bersih Entitas Asosiasi (%) | B8: =B5 -> 0.21182566 | C8: =C5 -> 0.32591668 | D8: =D5 -> 0.32591668 | E8: =E5 -> 0.32591668 | F8: =F5 -> 0.32591668
A9: Tingkat Bunga Efektif Atas Utang (%) | B9: =AVERAGE(ABS('Income Statement'!$I$14)/'Key Ratio'!$I$25,ABS('Income Statement'!$J$14)/'Key Ratio'!$J$25,ABS('Income Statement'!$K$14)/'Key Ratio'!$K$25) -> 0.073756823 | C9: =AVERAGE(ABS('Income Statement'!$I$14)/'Key Ratio'!$I$25,ABS('Income Statement'!$J$14)/'Key Ratio'!$J$25,ABS('Income Statement'!$K$14)/'Key Ratio'!$K$25) -> 0.073756823 | D9: =AVERAGE(ABS('Income Statement'!$I$14)/'Key Ratio'!$I$25,ABS('Income Statement'!$J$14)/'Key Ratio'!$J$25,ABS('Income Statement'!$K$14)/'Key Ratio'!$K$25) -> 0.073756823 | E9: =AVERAGE(ABS('Income Statement'!$I$14)/'Key Ratio'!$I$25,ABS('Income Statement'!$J$14)/'Key Ratio'!$J$25,ABS('Income Statement'!$K$14)/'Key Ratio'!$K$25) -> 0.073756823 | F9: =AVERAGE(ABS('Income Statement'!$I$14)/'Key Ratio'!$I$25,ABS('Income Statement'!$J$14)/'Key Ratio'!$J$25,ABS('Income Statement'!$K$14)/'Key Ratio'!$K$25) -> 0.073756823
A10: Tarif Pajak Efektif (%) | B10: =AVERAGE(ABS('Income Statement'!$I$21)/'Income Statement'!$I$20,ABS('Income Statement'!$J$21)/'Income Statement'!$J$20,ABS('Income Statement'!$K$21)/'Income Statement'!$K$20) -> 0.32249078 | C10: =AVERAGE(ABS('Income Statement'!$I$21)/'Income Statement'!$I$20,ABS('Income Statement'!$J$21)/'Income Statement'!$J$20,ABS('Income Statement'!$K$21)/'Income Statement'!$K$20) -> 0.32249078 | D10: =AVERAGE(ABS('Income Statement'!$I$21)/'Income Statement'!$I$20,ABS('Income Statement'!$J$21)/'Income Statement'!$J$20,ABS('Income Statement'!$K$21)/'Income Statement'!$K$20) -> 0.32249078 | E10: =AVERAGE(ABS('Income Statement'!$I$21)/'Income Statement'!$I$20,ABS('Income Statement'!$J$21)/'Income Statement'!$J$20,ABS('Income Statement'!$K$21)/'Income Statement'!$K$20) -> 0.32249078 | F10: =AVERAGE(ABS('Income Statement'!$I$21)/'Income Statement'!$I$20,ABS('Income Statement'!$J$21)/'Income Statement'!$J$20,ABS('Income Statement'!$K$21)/'Income Statement'!$K$20) -> 0.32249078
A11: Persentase Laba Bersih Milik Pemilik Entitas Induk (%) | B11: =AVERAGE('Income Statement'!$I$30/'Income Statement'!$I$25,'Income Statement'!$J$30/'Income Statement'!$J$25,'Income Statement'!$K$30/'Income Statement'!$K$25) -> 0.8670441 | C11: =AVERAGE('Income Statement'!$I$30/'Income Statement'!$I$25,'Income Statement'!$J$30/'Income Statement'!$J$25,'Income Statement'!$K$30/'Income Statement'!$K$25) -> 0.8670441 | D11: =AVERAGE('Income Statement'!$I$30/'Income Statement'!$I$25,'Income Statement'!$J$30/'Income Statement'!$J$25,'Income Statement'!$K$30/'Income Statement'!$K$25) -> 0.8670441 | E11: =AVERAGE('Income Statement'!$I$30/'Income Statement'!$I$25,'Income Statement'!$J$30/'Income Statement'!$J$25,'Income Statement'!$K$30/'Income Statement'!$K$25) -> 0.8670441 | F11: =AVERAGE('Income Statement'!$I$30/'Income Statement'!$I$25,'Income Statement'!$J$30/'Income Statement'!$J$25,'Income Statement'!$K$30/'Income Statement'!$K$25) -> 0.8670441
A12: Rasio Pembayaran Dividen (% Dari Laba Bersih Pemilik Tahun Sebelumnya) | B12: =AVERAGE(ABS('Cash Flow'!$B$49)/'Income Statement'!$J$30,ABS('Cash Flow'!$C$49)/'Income Statement'!$I$30) -> 0.51703767 | C12: =AVERAGE(ABS('Cash Flow'!$B$49)/'Income Statement'!$J$30,ABS('Cash Flow'!$C$49)/'Income Statement'!$I$30) -> 0.51703767 | D12: =AVERAGE(ABS('Cash Flow'!$B$49)/'Income Statement'!$J$30,ABS('Cash Flow'!$C$49)/'Income Statement'!$I$30) -> 0.51703767 | E12: =AVERAGE(ABS('Cash Flow'!$B$49)/'Income Statement'!$J$30,ABS('Cash Flow'!$C$49)/'Income Statement'!$I$30) -> 0.51703767 | F12: =AVERAGE(ABS('Cash Flow'!$B$49)/'Income Statement'!$J$30,ABS('Cash Flow'!$C$49)/'Income Statement'!$I$30) -> 0.51703767
A13: Belanja Modal / Capex (% Pendapatan) | B13: =AVERAGE(ABS('Cash Flow'!$B$21)/'Income Statement'!$K$5,ABS('Cash Flow'!$C$21)/'Income Statement'!$J$5,ABS('Cash Flow'!$D$21)/'Income Statement'!$I$5) -> 0.12777186 | C13: =AVERAGE(ABS('Cash Flow'!$B$21)/'Income Statement'!$K$5,ABS('Cash Flow'!$C$21)/'Income Statement'!$J$5,ABS('Cash Flow'!$D$21)/'Income Statement'!$I$5) -> 0.12777186 | D13: =AVERAGE(ABS('Cash Flow'!$B$21)/'Income Statement'!$K$5,ABS('Cash Flow'!$C$21)/'Income Statement'!$J$5,ABS('Cash Flow'!$D$21)/'Income Statement'!$I$5) -> 0.12777186 | E13: =AVERAGE(ABS('Cash Flow'!$B$21)/'Income Statement'!$K$5,ABS('Cash Flow'!$C$21)/'Income Statement'!$J$5,ABS('Cash Flow'!$D$21)/'Income Statement'!$I$5) -> 0.12777186 | F13: =AVERAGE(ABS('Cash Flow'!$B$21)/'Income Statement'!$K$5,ABS('Cash Flow'!$C$21)/'Income Statement'!$J$5,ABS('Cash Flow'!$D$21)/'Income Statement'!$I$5) -> 0.12777186
A14: Arus Kas Operasi / OCF (% Pendapatan) | B14: =AVERAGE('Key Ratio'!$I$53/'Income Statement'!$I$5,'Key Ratio'!$J$53/'Income Statement'!$J$5,'Key Ratio'!$K$53/'Income Statement'!$K$5) -> 0.20316143 | C14: =AVERAGE('Key Ratio'!$I$53/'Income Statement'!$I$5,'Key Ratio'!$J$53/'Income Statement'!$J$5,'Key Ratio'!$K$53/'Income Statement'!$K$5) -> 0.20316143 | D14: =AVERAGE('Key Ratio'!$I$53/'Income Statement'!$I$5,'Key Ratio'!$J$53/'Income Statement'!$J$5,'Key Ratio'!$K$53/'Income Statement'!$K$5) -> 0.20316143 | E14: =AVERAGE('Key Ratio'!$I$53/'Income Statement'!$I$5,'Key Ratio'!$J$53/'Income Statement'!$J$5,'Key Ratio'!$K$53/'Income Statement'!$K$5) -> 0.20316143 | F14: =AVERAGE('Key Ratio'!$I$53/'Income Statement'!$I$5,'Key Ratio'!$J$53/'Income Statement'!$J$5,'Key Ratio'!$K$53/'Income Statement'!$K$5) -> 0.20316143
A15: Pertumbuhan Total Debt (%) | B15: 0 | C15: 0 | D15: 0 | E15: 0 | F15: 0
A16: Asumsi Perputaran Aset / Asset Turnover (x) | B16: =AVERAGE('Key Ratio'!$I$48,'Key Ratio'!$J$48,'Key Ratio'!$K$48) -> 0.70421678 | C16: =AVERAGE('Key Ratio'!$I$48,'Key Ratio'!$J$48,'Key Ratio'!$K$48) -> 0.70421678 | D16: =AVERAGE('Key Ratio'!$I$48,'Key Ratio'!$J$48,'Key Ratio'!$K$48) -> 0.70421678 | E16: =AVERAGE('Key Ratio'!$I$48,'Key Ratio'!$J$48,'Key Ratio'!$K$48) -> 0.70421678 | F16: =AVERAGE('Key Ratio'!$I$48,'Key Ratio'!$J$48,'Key Ratio'!$K$48) -> 0.70421678
A17: Proporsi Kepentingan Non Pengendali (% Dari Total Ekuitas) | B17: ='Balance Sheet'!$K$75/'Balance Sheet'!$K$77 -> 0.16732882 | C17: ='Balance Sheet'!$K$75/'Balance Sheet'!$K$77 -> 0.16732882 | D17: ='Balance Sheet'!$K$75/'Balance Sheet'!$K$77 -> 0.16732882 | E17: ='Balance Sheet'!$K$75/'Balance Sheet'!$K$77 -> 0.16732882 | F17: ='Balance Sheet'!$K$75/'Balance Sheet'!$K$77 -> 0.16732882
